Workbook

Sheet Item-per-dimensi
B2: N (Need to finish a task) | F2: B (Need to belong to groups)
B3: Nomor | C3: Item | F3: Nomor | G3: Item
B4: 2B | C4: Saya suka menekuni pekerjaan yang saya lakukan sampai selesai. | F4: 35A | G4: Saya ingin menjadi bagian dari kelompok.
B5: 13B | C5: Saya selalu menekuni suatu pekerjaan sampai selesai. | F5: 25A | G5: Saya ingin menyelaraskan diri dengan kelompok.
B6: 24B | C6: Saya tidak suka mengerjakan beberapa pekerjaan sekaligus. | F6: 15A | G6: Saya ingin diterima dalam kelompok.
B7: 35B | C7: Saya ingin menyelesaikan pekerjaan satu per satu. | F7: 5A | G7: Saya suka bergabung dalam kelompok.
B8: 46B | C8: Saya selalu berusaha menyelesaikan apa yang sudah saya mulai. | F8: 6A | G8: Saya suka berteman dengan suatu kelompok.
B9: 57B | C9: Saya selalu ingin menyelesaikan pekerjaan yang telah saya mulai. | F9: 17B | G9: Saya lebih suka bekerja bersama orang Iain daripada sendiri.
B10: 68B | C10: Saya terus menekuni suatu masalah sampai terselesaikan. | F10: 28B | G10: Saya ingin diterima dan diakui dalam suatu kelompok.
B11: 79B | C11: Saya selalu menyelesaikan pekerjaan yang telah saya mulai. | F11: 39B | G11: Saya tertarik menjadi bagian dari kelompok.
B12: 90B | C12: Saya harus menyelesaikan apa yang sudah saya mulai. | F12: 50B | G12: Saya senang berada bersama dengan orang-orang Iain.
B14: G (Role of Hard Intense Worker) | F14: O (Need for closeness and affection)
B15: Nomor | C15: Item | F15: Nomor | G15: Item
B16: 1A | C16: Saya seorang pekerja keras. | F16: 46A | G16: Saya senang bila orang-orang dapat intim dan bersahabat.
B17: 11A | C17: Saya mencoba sekuat tenaga. | F17: 36A | G17: Saya berusaha berteman secara akrab.
B18: 21A | C18: Saya selalu berusaha keras. | F18: 26A | G18: Saya suka membina hubungan yang akrab dengan teman-teman saya.
B19: 31A | C19: Saya bekerja keras. | F19: 16A | G19: Saya cemas jika seseorang tidak menyukai saya.
B20: 41A | C20: Saya berusaha keras sekali. | F20: 6B | G20: Saya senang bersahabat intim dengan seseorang.
B21: 51A | C21: Saya selalu berusaha menyelesaikan tugas secara sempurna. | F21: 7B | G21: Saya berusaha membina hubungan yang akrab dengan teman saya.
B22: 61A | C22: Saya berusaha kerja keras. | F22: 18B | G22: Saya merasa terganggu jika ada orang yang tidak menyukai saya.
B23: 71A | C23: Saya selalu berusaha bekerja keras. | F23: 29B | G23: Saya cemas kalau orang Iain tidak menyukai saya.
B24: 81A | C24: Saya mengejar apa yang saya inginkan. | F24: 40B | G24: Saya suka orang mengenal saya dengan baik.
B26: A (Need to Achieve) | F26: R (Theoritical type)
B27: Nomor | C27: Item | F27: Nomor | G27: Item
B28: 2A | C28: Saya suka bekerja lebih baik dari orang lain. | F28: 67A | G28: Perencanaan saya jauh ke masa depan.
B29: 3B | C29: Saya ingin bekerja sebaik mungkin. | F29: 77A | G29: Saya banyak berpikir dan merencanakan.
B30: 14B | C30: Saya ingin menjadi sangat sukses. | F30: 87B | G30: Saya bekerja dengan teori.
B31: 25B | C31: Saya ingin melakukan sesuatu lebih baik dari orang lain. | F31: 86B | G31: Saya banyak menghabiskan waktu untuk berpikir.
B32: 36B | C32: Saya berusaha keras untuk menjadi yang terbaik. | F32: 75B | G32: Sebagian besar waktu saya gunakan untuk berpikir.
B33: 47B | C33: Saya suka mengerjakan tugas-tugas yang sulit dengan balk. | F33: 64B | G33: Saya senang bekerja berdasarkan teori atau konsep tertentu.
B34: 58B | C34: Saya ingin menjadi orang yang berhasil. | F34: 53B | G34: Saya banyak mempertimbangkan konsep dan ide-ide.
B35: 69B | C35: Saya ingin sukses. | F35: 42B | G35: Saya berpikir panjang dan hati-hati.
B36: 80B | C36: Saya suka menjadi orang yang sukses. | F36: 31B | G36: Saya banyak berpikir dan berencana.
B38: L (Leadership Roles) | F38: D (Interest in working with detail)
B39: Nomor | C39: Item | F39: Nomor | G39: Item
B40: 12A | C40: Saya dapat membuat orang mau bekerja keras. | F40: 78A | G40: Saya suka pekerjaan yang harus memperhatikan hal-hal kecil (detail).
B41: 22A | C41: Saya adalah pemimpin yang baik. | F41: 88A | G41: Saya menikmati pekerjaan yang melibatkan hal detail.
B42: 32A | C42: Saya memimpin kelompok. | F42: 87A | G42: Saya suka bekerja dengan hal-hal yang terperinci.
B43: 42A | C43: Orang lain beranggapan bahwa saya adalah seorang pemimpin yang baik. | F43: 76B | G43: Saya menyukai pekerjaan yang menuntut ketepatan.
B44: 52A | C44: Saya tergolong tipe pemimpin. | F44: 65B | G44: Saya menyukai pekerjaan yang harus dilakukan secara teliti.
...

Sheet Item_Table
B1: Nomor | C1: Item | D1: Aspek
A2: 1 | B2: 2B | C2: Saya suka menekuni pekerjaan yang saya lakukan sampai selesai. | D2: N
A3: 2 | B3: 13B | C3: Saya selalu menekuni suatu pekerjaan sampai selesai. | D3: N
A4: 3 | B4: 24B | C4: Saya tidak suka mengerjakan beberapa pekerjaan sekaligus. | D4: N
A5: 4 | B5: 35B | C5: Saya ingin menyelesaikan pekerjaan satu per satu. | D5: N
A6: 5 | B6: 46B | C6: Saya selalu berusaha menyelesaikan apa yang sudah saya mulai. | D6: N
A7: 6 | B7: 57B | C7: Saya selalu ingin menyelesaikan pekerjaan yang telah saya mulai. | D7: N
A8: 7 | B8: 68B | C8: Saya terus menekuni suatu masalah sampai terselesaikan. | D8: N
A9: 8 | B9: 79B | C9: Saya selalu menyelesaikan pekerjaan yang telah saya mulai. | D9: N
A10: 9 | B10: 90B | C10: Saya harus menyelesaikan apa yang sudah saya mulai. | D10: N
A11: 10 | B11: 1A | C11: Saya seorang pekerja keras. | D11: G
A12: 11 | B12: 11A | C12: Saya mencoba sekuat tenaga. | D12: G
A13: 12 | B13: 21A | C13: Saya selalu berusaha keras. | D13: G
... A181: 180 | B181: 10B | C181: Saya suka mengikuti petunjuk kerja yang diberikan pada saya. | D181: W

Sheet Item-per-block
B2: No | C2: Kode | D2: Pernyataan A | E2: Kode | F2: Pernyataan B
B3: 1 | C3: 1A | D3: {=XLOOKUP(C3,Item_Table!$B$2:$B$181,Item_Table!$C$2:$C$181,"",0)} -> Saya seorang pekerja keras. | E3: 1B | F3: {=XLOOKUP(E3,Item_Table!$B$2:$B$181,Item_Table!$C$2:$C$181,"",0)} -> Saya bukan seorang pemurung.
B4: 2 | C4: 2A | D4: {=XLOOKUP(C4,Item_Table!$B$2:$B$181,Item_Table!$C$2:$C$181,"",0)} -> Saya suka bekerja lebih baik dari orang lain. | E4: 2B | F4: {=XLOOKUP(E4,Item_Table!$B$2:$B$181,Item_Table!$C$2:$C$181,"",0)} -> Saya suka menekuni pekerjaan yang saya lakukan sampai selesai.
B5: 3 | C5: 3A | D5: {=XLOOKUP(C5,Item_Table!$B$2:$B$181,Item_Table!$C$2:$C$181,"",0)} -> Saya suka memberi petunjuk kepada orang bagaimana melakukan sesuatu. | E5: 3B | F5: {=XLOOKUP(E5,Item_Table!$B$2:$B$181,Item_Table!$C$2:$C$181,"",0)} -> Saya ingin bekerja sebaik mungkin.
B6: 4 | C6: 4A | D6: {=XLOOKUP(C6,Item_Table!$B$2:$B$181,Item_Table!$C$2:$C$181,"",0)} -> Saya senang memberitahu orang apa yang harus dikerjakannya. | E6: 4B | F6: {=XLOOKUP(E6,Item_Table!$B$2:$B$181,Item_Table!$C$2:$C$181,"",0)} -> Saya suka melakukan hal-hal yang lucu.
B7: 5 | C7: 5A | D7: {=XLOOKUP(C7,Item_Table!$B$2:$B$181,Item_Table!$C$2:$C$181,"",0)} -> Saya suka bergabung dalam kelompok. | E7: 5B | F7: {=XLOOKUP(E7,Item_Table!$B$2:$B$181,Item_Table!$C$2:$C$181,"",0)} -> Saya senang diperhatikan oleh kelompok.
B8: 6 | C8: 6A | D8: {=XLOOKUP(C8,Item_Table!$B$2:$B$181,Item_Table!$C$2:$C$181,"",0)} -> Saya suka berteman dengan suatu kelompok. | E8: 6B | F8: {=XLOOKUP(E8,Item_Table!$B$2:$B$181,Item_Table!$C$2:$C$181,"",0)} -> Saya senang bersahabat intim dengan seseorang.
B9: 7 | C9: 7A | D9: {=XLOOKUP(C9,Item_Table!$B$2:$B$181,Item_Table!$C$2:$C$181,"",0)} -> Saya cepat berubah jika hal itu diperlukan. | E9: 7B | F9: {=XLOOKUP(E9,Item_Table!$B$2:$B$181,Item_Table!$C$2:$C$181,"",0)} -> Saya berusaha membina hubungan yang akrab dengan teman saya.
B10: 8 | C10: 8A | D10: {=XLOOKUP(C10,Item_Table!$B$2:$B$181,Item_Table!$C$2:$C$181,"",0)} -> Saya ingin mencoba sesuatu yang baru dan bervariasi. | E10: 8B | F10: {=XLOOKUP(E10,Item_Table!$B$2:$B$181,Item_Table!$C$2:$C$181,"",0)} -> Saya ingin membalas bisa disakiti.
B11: 9 | C11: 9A | D11: {=XLOOKUP(C11,Item_Table!$B$2:$B$181,Item_Table!$C$2:$C$181,"",0)} -> Saya ingin atasan saya menyukai saya. | E11: 9B | F11: {=XLOOKUP(E11,Item_Table!$B$2:$B$181,Item_Table!$C$2:$C$181,"",0)} -> Saya suka memberitahu orang lain jika mereka salah.
B12: 10 | C12: 10A | D12: {=XLOOKUP(C12,Item_Table!$B$2:$B$181,Item_Table!$C$2:$C$181,"",0)} -> Saya suka menyenangkan hati orang yang memimpin saya. | E12: 10B | F12: {=XLOOKUP(E12,Item_Table!$B$2:$B$181,Item_Table!$C$2:$C$181,"",0)} -> Saya suka mengikuti petunjuk kerja yang diberikan pada saya.
B13: 11 | C13: 11A | D13: {=XLOOKUP(C13,Item_Table!$B$2:$B$181,Item_Table!$C$2:$C$181,"",0)} -> Saya mencoba sekuat tenaga. | E13: 11B | F13: {=XLOOKUP(E13,Item_Table!$B$2:$B$181,Item_Table!$C$2:$C$181,"",0)} -> Saya menempatkan semua barang pada tempatnya.
B14: 12 | C14: 12A | D14: {=XLOOKUP(C14,Item_Table!$B$2:$B$181,Item_Table!$C$2:$C$181,"",0)} -> Saya dapat membuat orang mau bekerja keras. | E14: 12B | F14: {=XLOOKUP(E14,Item_Table!$B$2:$B$181,Item_Table!$C$2:$C$181,"",0)} -> Saya tidak mudah marah.
... B92: 90 | C92: 90A | D92: {=XLOOKUP(C92,Item_Table!$B$2:$B$181,Item_Table!$C$2:$C$181,"",0)} -> Saya senang diberi petunjuk mengenai apa yang harus saya lakukan. | E92: 90B | F92: {=XLOOKUP(E92,Item_Table!$B$2:$B$181,Item_Table!$C$2:$C$181,"",0)} -> Saya harus menyelesaikan apa yang sudah saya mulai.
